<mujocoinclude>
    <!--  ================= Base ================= /-->
    <body name='l_arm_l6' pos='-1 -1.11 1.5' euler="0 3.14 0">
        <inertial pos='-8.0726e-06 0.0085838 -0.0049566' quat='0.479044 0.515636 -0.513069 0.491322' mass='0.3292'
                  diaginertia='0.000360258 0.000311068 0.000214974'/>
        <!-- <joint name='arm_j6' pos='0 0 0' axis='0 0 1' range='-4.7124 4.7124' /> -->
        <!--<freejoint />-->
        <joint axis="1 0 0" damping="0.001" name="arm_slide0" pos="0 0 0" type="slide"/>
        <joint axis="0 1 0" damping="0.001" name="arm_slide1" pos="0 0 0" type="slide"/>
        <joint axis="0 0 1" damping="0.001" name="arm_slide2" pos="0 0 0" type="slide"/>
        <!--  ================================== /-->
        <body name='l_gripper_origin' pos='0 0 0.18735' quat='0.707107 0 0 0.707107'>
            <!-- <site name='gripper_origin' size='0.005' pos='0 0 0' rgba='0 0.5 0 0.25' quat='1 0 0 0'/> -->
        </body>
        <!--  ================================== /-->
        <geom type='mesh' contype='0' conaffinity='0' group='1' rgba='0.5 0.1 0.1 1' mesh='l6'/>
        <geom size='0.055 0.025' pos='0 0.015 -0.01' type='cylinder' rgba='0.5 0.1 0.1 1'/>
        <body name='l_arm_hand' pos='0 0 0.0245' quat='0.707107 0 0 0.707107'>
            <inertial pos='1e-08 1e-08 1e-08' quat='0.820473 0.339851 -0.17592 0.424708' mass='1e-08'
                      diaginertia='1e-08 1e-08 1e-08'/>
            <geom size='0.035 0.015' pos='0 0 0.02' type='cylinder'/>
            <!--  ================= Gripper ================= /-->
            <body name='l_arm_gripper_base' pos='0 0 0.025'>
                <inertial pos='0 0 0' quat='-0.5 0.5 0.5 0.5' mass='0.3' diaginertia='3e-08 2e-08 2e-08'/>
                <geom quat='0 0 0.707107 0.707107' class='viz' mesh='electric_gripper_base'/>
                <geom size='0.029 0.05' quat='0 0 0.707107 0.707107' type='cylinder'/>
                <!--<body name='arm_gripper' pos='0 0 0.1327'>
                    <inertial pos='0 0 0' mass='0.0001' diaginertia='0 0 0' />
                </body>-->
                <body name='l_finger_l' pos='0 -0.0015 0.02'>
                    <inertial pos='0 0 0' quat='0 0 0 -1' mass='0.02' diaginertia='0.01 0.01 0.01'/>
                    <joint name='l_gripper_jl' solreflimit="0.006 1" solimplimit="0.99 0.999 0.001" pos='0 0 0'
                           axis='0 1 0' type='slide' range='0 0.020833' springdamper='0.08 6' limited='true'/>
                    <geom class='viz' mesh='extended_narrow' euler='1.57 1.57 0' rgba='0.1 0.1 0.1 1'/>
                    <geom size='0.005 0.00675 0.05635' pos='0 0.01725 0.0615' quat='0 0 0 -1' type='box'
                          rgba='0.1 0.1 0.1 1'/>
                    <geom size='0.005 0.025 0.0085' pos='-0.005 -0.003 0.0083' quat='0 0 0 -1' type='box'
                          rgba='0.1 0.1 0.1 1'/>
                    <geom size='0.01 0.005 0.025' pos='0 0.012 0.095' type='box' rgba='0.3 0.3 0.3 0.9'
                          class='gripper_pads'/>
                    <!--  === Sensors === /-->
                    <!-- <body name='sensor_array_l' pos='0 0.007 0.1' quat='0 0 0 1' childclass='takktile_unit'>
                        <geom pos='0.0045 0.002 -0.016'/>
                        <site name='sensor_tl0' pos='0.0045 0.004 -0.016'/>
                        <geom pos='-0.0045 0.002 -0.016' />
                        <site name='sensor_tl1' pos='-0.0045 0.004 -0.016'/>
                        <geom pos='0.0045 0.002 -0.008'/>
                        <site name='sensor_tl2' pos='0.0045 0.004 -0.008'/>
                        <geom pos='-0.0045 0.002 -0.008'/>
                        <site name='sensor_tl3' pos='-0.0045 0.004 -0.008'/>
                        <geom pos='0.0045 0.002 0'/>
                        <site name='sensor_tl4' pos='0.0045 0.004 0'/>
                        <geom pos='-0.0045 0.002 0'/>
                        <site name='sensor_tl5' pos='-0.0045 0.004 0'/>
                        <geom pos='0.0045 0.002 0.008'/>
                        <site name='sensor_tl6' pos='0.0045 0.004 0.008'/>
                        <geom pos='-0.0045 0.002 0.008'/>
                        <site name='sensor_tl7' pos='-0.0045 0.004 0.008'/>
                        <geom pos='0.0045 0.002 0.016'/>
                        <site name='sensor_tl8' pos='0.0045 0.004 0.016'/>
                        <geom pos='-0.0045 0.002 0.016'/>
                        <site name='sensor_tl9' pos='-0.0045 0.004 0.016'/>
                    </body> -->

                    <!-- <body name='r_gripper_l_finger_tip' pos='0 0.01725 0.1127'>
                        <inertial pos='0 0 0' quat='0 0 0 1' mass='0.01' diaginertia='0.01 0.01 0.01' />
                        <geom pos='-.007 -.01 0.003' class='viz' mesh='half_round_tip' euler='-1.57 0 0'/>
                        <geom size='0.008 0.0185' pos='0 -0.0045 -0.015' quat='0 0 0 1' type='cylinder' />
                    </body> -->

                </body>
                <body name='l_finger_r' pos='0 0.0015 0.02'>
                    <inertial pos='0 0 0' mass='0.02' diaginertia='0.01 0.01 0.01'/>
                    <joint name='l_gripper_jr' solreflimit="0.006 1" solimplimit="0.99 0.999 0.001" pos='0 0 0'
                           axis='0 1 0' type='slide' range='-0.020833 0' springdamper='0.08 6' limited='true'/>
                    <geom class='viz' mesh='extended_narrow' euler='1.57 -1.57 0' rgba='0.1 0.1 0.1 1'/>
                    <geom size='0.005 0.00675 0.05635' pos='0 -0.01725 0.0615' type='box' rgba='0.1 0.1 0.1 1'/>
                    <geom size='0.005 0.025 0.0085' pos='0.005 0.003 0.0083' type='box' rgba='0.1 0.1 0.1 1'/>
                    <geom size='0.01 0.005 0.025' pos='0 -0.012 0.095' type='box' rgba='0.3 0.3 0.3 0.9'
                          class='gripper_pads'/>
                    <!--  === Sensors === /-->
                    <!-- <body name='sensor_array_r' pos='0 -0.007 0.1' quat='1 0 0 0' childclass='takktile_unit'>
                        <geom pos='0.0045 0.002 -0.016'/>
                        <site name='sensor_tr0' pos='0.0045 0.004 -0.016'/>
                        <geom pos='-0.0045 0.002 -0.016' />
                        <site name='sensor_tr1' pos='-0.0045 0.004 -0.016'/>
                        <geom pos='0.0045 0.002 -0.008'/>
                        <site name='sensor_tr2' pos='0.0045 0.004 -0.008'/>
                        <geom pos='-0.0045 0.002 -0.008'/>
                        <site name='sensor_tr3' pos='-0.0045 0.004 -0.008'/>
                        <geom pos='0.0045 0.002 0'/>
                        <site name='sensor_tr4' pos='0.0045 0.004 0'/>
                        <geom pos='-0.0045 0.002 0'/>
                        <site name='sensor_tr5' pos='-0.0045 0.004 0'/>
                        <geom pos='0.0045 0.002 0.008'/>
                        <site name='sensor_tr6' pos='0.0045 0.004 0.008'/>
                        <geom pos='-0.0045 0.002 0.008'/>
                        <site name='sensor_tr7' pos='-0.0045 0.004 0.008'/>
                        <geom pos='0.0045 0.002 0.016'/>
                        <site name='sensor_tr8' pos='0.0045 0.004 0.016'/>
                        <geom pos='-0.0045 0.002 0.016'/>
                        <site name='sensor_tr9' pos='-0.0045 0.004 0.016'/>
                    </body> -->

                    <!-- <body name='r_gripper_r_finger_tip' pos='0 -0.01725 0.1127'>
                        <inertial pos='0 0 0' mass='0.01' diaginertia='0.01 0.01 0.01' />
                        <geom pos='.007 .01 0.003' class='viz' mesh='half_round_tip' euler='-1.57 3.14 0'/>
                        <geom size='0.008 0.0185' pos='0 0.0045 -0.015' type='cylinder' />
                    </body> -->

                </body>
            </body>
        </body>
    </body>

</mujocoinclude>