<mujoco model='sawyer'>
    <compiler angle='radian' coordinate='local' meshdir='./dfm_env/meshes'/>
    <option collision='all' impratio='1' cone='elliptic' timestep='0.001' gravity='0 0 -9.8' viscosity='0'
            iterations='20'/>
    <!--
    <size njmax='600' nconmax='150' />
    -->
    <size njmax='3000' nconmax='2000'/>

    <!--  ================= Visual Elements ================= /-->
    <asset>
        <mesh name='pedestal' file='sawyer_meshes/arm/pedestal.stl'/>
        <mesh name='base' file='sawyer_meshes/arm/base.stl'/>
        <mesh name='l0' file='sawyer_meshes/arm/l0.stl'/>
        <mesh name='head' file='sawyer_meshes/arm/head.stl'/>
        <mesh name='l1' file='sawyer_meshes/arm/l1.stl'/>
        <mesh name='l2' file='sawyer_meshes/arm/l2.stl'/>
        <mesh name='l3' file='sawyer_meshes/arm/l3.stl'/>
        <mesh name='l4' file='sawyer_meshes/arm/l4.stl'/>
        <mesh name='l5' file='sawyer_meshes/arm/l5.stl'/>
        <mesh name='l6' file='sawyer_meshes/arm/l6.stl'/>
        <mesh name='half_round_tip' file='sawyer_meshes/electric_gripper/fingers/half_round_tip.stl'/>
        <mesh name='electric_gripper_base' file='sawyer_meshes/electric_gripper/electric_gripper_base.stl'/>
        <mesh name='extended_narrow' file='sawyer_meshes/electric_gripper/fingers/extended_narrow.stl'/>
        <mesh name='paddle_tip' file='sawyer_meshes/electric_gripper/fingers/paddle_tip.stl'/>
    </asset>

    <!--  ================= Physical Properties ================= /-->
    <default>
        <geom solref='0.01 1' solimp='0.95 0.95 0.01' condim='4'/>

        <default class='arm'>
            <!--<geom material='MatGnd' rgba='.7 .4 .2 1' solref='0.01 1' solimp='0.95 0.98 0.001' contype='1' condim='1'-->
            <!--conaffinity='1'/>-->
            <geom condim='1' friction='0 0 0' density='2700' contype='1' conaffinity='1'/>
            <joint limited='true' damping='1'/>
        </default>

        <default class='viz'>
            <geom contype='0' conaffinity='0' group='1' type='mesh'/>
        </default>

        <default class='gripper'>
            <geom condim='4' density='2700'/>
            <joint limited='true' damping='0.001' stiffness='0.1' springref='0'/>
        </default>

        <default class='gripper_pads'>
            <geom friction='1 0.005 0.0001' solref='0.01 1' solimp='0.95 0.98 0.001' condim='4' density='100'/>
        </default>

        <default class='takktile_unit'>
            <geom friction='5 0.003 0.0001' solref='0.008 1' solimp='0.95 0.99 0.0001' condim='6' density='300'
                  size='0.003 0.002 0.003' type='box' rgba='0.9 0.9 0.1 1'/>
            <site size='0.0035 0.001 0.0035' type='box' rgba='0.9 0.9 0.3 0.2'/>
        </default>
    </default>


    <!--  ================= Kinematic Tree ================= /-->
    <worldbody>
        <light directional='true' cutoff='40' exponent='10' diffuse='.4 .4 .4' specular='.7 .7 .7' pos='0.9 0 1.5'
               dir='0 0 -1' castshadow="false"/>
        <!--Tilted view-->
        <!--<camera name='static_camera' pos='0.0 -0.28 2.1' euler='0.3 0 0'/>-->
        <!--Top down view, camera v1-->
<!--        <camera name='static_camera' pos='0.0 0.25 2.1' euler='0. 0 0'/>-->
        <!--Top down view, camera v2-->
        <camera name='static_camera' pos='0.0 0.35 1.7' euler='0. 0 0'/>

        <!--================= Mocap =================-->
        <!--<body name="mocap_body" pos="0 0 0" mocap="true">-->
            <!--<geom conaffinity="0" contype="0" pos="0 0 0" rgba="0 0.5 0 0.7" size="0.005 0.005 0.005" type="box"></geom>-->
            <!--<geom conaffinity="0" contype="0" pos="0 0 0" rgba="0 0.5 0 0.1" size="1 0.005 0.005" type="box"></geom>-->
            <!--<geom conaffinity="0" contype="0" pos="0 0 0" rgba="0 0.5 0 0.1" size="0.005 1 0.001" type="box"></geom>-->
            <!--<geom conaffinity="0" contype="0" pos="0 0 0" rgba="0 0.5 0 0.1" size="0.005 0.005 1" type="box"></geom>-->
        <!--</body>-->
        <!---->
        <body name='arm_l6' pos='-0 0 0' quat='0 1 0 0'>
            <inertial pos='-8.0726e-06 0.0085838 -0.0049566' quat='0.479044 0.515636 -0.513069 0.491322' mass='0.3292'
                      diaginertia='0.000360258 0.000311068 0.000214974'/>
            <joint axis="1 0 0" damping="0.001" name="arm_slide0" pos="0 0 0" type="slide"/>
            <joint axis="0 -1 0" damping="0.001" name="arm_slide1" pos="0 0 0" type="slide"/>
            <joint axis="0 0 -1" damping="0.001" name="arm_slide2" pos="0 0 0" type="slide"/>
            <!--  ================================== /-->
            <!--<body name='gripper_origin' pos='0 0 0.18735' quat='0.707107 0 0 0.707107'>-->
                <!--<site name='gripper_origin' size='0.005' pos='0 0 0' rgba='0 0.5 0 0.25' quat='1 0 0 0'/>-->
            <!--</body>-->
            <!--  ================================== /-->
            <geom type='mesh' contype='0' conaffinity='0' group='1' rgba='0.5 0.1 0.1 1' mesh='l6'/>
            <geom size='0.055 0.025' pos='0 0.015 -0.01' type='cylinder' rgba='0.5 0.1 0.1 1'/>
            <body name='arm_hand' pos='0 0 0.0245' quat='0.707107 0 0 0.707107'>
                <inertial pos='1e-08 1e-08 1e-08' quat='0.820473 0.339851 -0.17592 0.424708' mass='1e-08'
                          diaginertia='1e-08 1e-08 1e-08'/>
                <geom size='0.035 0.015' pos='0 0 0.02' type='cylinder'/>
                <!--  ================= Gripper ================= /-->
                <body name='arm_gripper_base' pos='0 0 0.025'>
                    <inertial pos='0 0 0' quat='-0.5 0.5 0.5 0.5' mass='0.3' diaginertia='3e-08 2e-08 2e-08'/>
                    <geom quat='0 0 0.707107 0.707107' class='viz' mesh='electric_gripper_base'/>
                    <geom size='0.029 0.05' quat='0 0 0.707107 0.707107' type='cylinder'/>
                    <!--<body name='arm_gripper' pos='0 0 0.1327'>
                        <inertial pos='0 0 0' mass='0.0001' diaginertia='0 0 0' />
                    </body>-->
                    <body name='finger_l' pos='0 -0.0015 0.02'>
                        <inertial pos='0 0 0' quat='0 0 0 -1' mass='0.02' diaginertia='0.01 0.01 0.01'/>
                        <!--<joint name='gripper_jl' pos='0 0 0' axis='0 1 0' type='slide' range='0 0.020833' springdamper='0.08 6' limited='true'/>-->
                        <geom class='viz' mesh='extended_narrow' euler='1.57 1.57 0' rgba='0.1 0.1 0.1 1'/>
                        <geom size='0.005 0.00675 0.05635' pos='0 0.01725 0.0615' quat='0 0 0 -1' type='box'
                              rgba='0.1 0.1 0.1 1'/>
                        <geom size='0.005 0.025 0.0085' pos='-0.005 -0.003 0.0083' quat='0 0 0 -1' type='box'
                              rgba='0.1 0.1 0.1 1'/>
                        <geom size='0.01 0.005 0.025' pos='0 0.012 0.095' type='box' rgba='0.3 0.3 0.3 0.9'
                              class='gripper_pads'/>
                        <!--  === Sensors === /-->
                        <!--<body name='sensor_array_l' pos='0 0.007 0.1' quat='0 0 0 1' childclass='takktile_unit'>-->
                            <!--<geom pos='0.0045 0.002 -0.016'/>-->
                            <!--<site name='sensor_tl0' pos='0.0045 0.004 -0.016'/>-->
                            <!--<geom pos='-0.0045 0.002 -0.016'/>-->
                            <!--<site name='sensor_tl1' pos='-0.0045 0.004 -0.016'/>-->
                            <!--<geom pos='0.0045 0.002 -0.008'/>-->
                            <!--<site name='sensor_tl2' pos='0.0045 0.004 -0.008'/>-->
                            <!--<geom pos='-0.0045 0.002 -0.008'/>-->
                            <!--<site name='sensor_tl3' pos='-0.0045 0.004 -0.008'/>-->
                            <!--<geom pos='0.0045 0.002 0'/>-->
                            <!--<site name='sensor_tl4' pos='0.0045 0.004 0'/>-->
                            <!--<geom pos='-0.0045 0.002 0'/>-->
                            <!--<site name='sensor_tl5' pos='-0.0045 0.004 0'/>-->
                            <!--<geom pos='0.0045 0.002 0.008'/>-->
                            <!--<site name='sensor_tl6' pos='0.0045 0.004 0.008'/>-->
                            <!--<geom pos='-0.0045 0.002 0.008'/>-->
                            <!--<site name='sensor_tl7' pos='-0.0045 0.004 0.008'/>-->
                            <!--<geom pos='0.0045 0.002 0.016'/>-->
                            <!--<site name='sensor_tl8' pos='0.0045 0.004 0.016'/>-->
                            <!--<geom pos='-0.0045 0.002 0.016'/>-->
                            <!--<site name='sensor_tl9' pos='-0.0045 0.004 0.016'/>-->
                        <!--</body>-->
                        <!--
                        <body name='r_gripper_l_finger_tip' pos='0 0.01725 0.1127'>
                            <inertial pos='0 0 0' quat='0 0 0 1' mass='0.01' diaginertia='0.01 0.01 0.01' />
                            <geom pos='-.007 -.01 0.003' class='viz' mesh='half_round_tip' euler='-1.57 0 0'/>
                            <geom size='0.008 0.0185' pos='0 -0.0045 -0.015' quat='0 0 0 1' type='cylinder' />
                        </body>
                        -->
                    </body>
                    <body name='finger_r' pos='0 0.0015 0.02'>
                        <inertial pos='0 0 0' mass='0.02' diaginertia='0.01 0.01 0.01'/>
                        <!--<joint name='gripper_jr' pos='0 0 0' axis='0 1 0' type='slide' range='-0.020833 0' springdamper='0.08 6' limited='true'/>-->
                        <geom class='viz' mesh='extended_narrow' euler='1.57 -1.57 0' rgba='0.1 0.1 0.1 1'/>
                        <geom size='0.005 0.00675 0.05635' pos='0 -0.01725 0.0615' type='box' rgba='0.1 0.1 0.1 1'/>
                        <geom size='0.005 0.025 0.0085' pos='0.005 0.003 0.0083' type='box' rgba='0.1 0.1 0.1 1'/>
                        <geom size='0.01 0.005 0.025' pos='0 -0.012 0.095' type='box' rgba='0.3 0.3 0.3 0.9'
                              class='gripper_pads'/>
                        <!--  === Sensors === /-->
                        <!--<body name='sensor_array_r' pos='0 -0.007 0.1' quat='1 0 0 0' childclass='takktile_unit'>-->
                            <!--<geom pos='0.0045 0.002 -0.016'/>-->
                            <!--<site name='sensor_tr0' pos='0.0045 0.004 -0.016'/>-->
                            <!--<geom pos='-0.0045 0.002 -0.016'/>-->
                            <!--<site name='sensor_tr1' pos='-0.0045 0.004 -0.016'/>-->
                            <!--<geom pos='0.0045 0.002 -0.008'/>-->
                            <!--<site name='sensor_tr2' pos='0.0045 0.004 -0.008'/>-->
                            <!--<geom pos='-0.0045 0.002 -0.008'/>-->
                            <!--<site name='sensor_tr3' pos='-0.0045 0.004 -0.008'/>-->
                            <!--<geom pos='0.0045 0.002 0'/>-->
                            <!--<site name='sensor_tr4' pos='0.0045 0.004 0'/>-->
                            <!--<geom pos='-0.0045 0.002 0'/>-->
                            <!--<site name='sensor_tr5' pos='-0.0045 0.004 0'/>-->
                            <!--<geom pos='0.0045 0.002 0.008'/>-->
                            <!--<site name='sensor_tr6' pos='0.0045 0.004 0.008'/>-->
                            <!--<geom pos='-0.0045 0.002 0.008'/>-->
                            <!--<site name='sensor_tr7' pos='-0.0045 0.004 0.008'/>-->
                            <!--<geom pos='0.0045 0.002 0.016'/>-->
                            <!--<site name='sensor_tr8' pos='0.0045 0.004 0.016'/>-->
                            <!--<geom pos='-0.0045 0.002 0.016'/>-->
                            <!--<site name='sensor_tr9' pos='-0.0045 0.004 0.016'/>-->
                        <!--</body>-->
                        <!--
                        <body name='r_gripper_r_finger_tip' pos='0 -0.01725 0.1127'>
                            <inertial pos='0 0 0' mass='0.01' diaginertia='0.01 0.01 0.01' />
                            <geom pos='.007 .01 0.003' class='viz' mesh='half_round_tip' euler='-1.57 3.14 0'/>
                            <geom size='0.008 0.0185' pos='0 0.0045 -0.015' type='cylinder' />
                        </body>
                        -->
                    </body>
                </body>
            </body>
        </body>
    </worldbody>

    <!--  ================= Constraints ================= /-->
    <!--<equality>-->
    <!--<joint joint1='gripper_jl' joint2='gripper_jr' polycoef='0 -1 0 0 0' solimp="0.99 0.999 0.001" solref="0.01 1"/>-->
    <!--</equality>-->

    <!--  ================= Actuators ================= /-->
    <actuator>
        <!--  ================= Torque actuators ================= /-->
        <motor ctrllimited='false' joint='arm_slide0' name='tj0'/>
        <motor ctrllimited='false' joint='arm_slide1' name='tj1'/>
        <motor ctrllimited='false' joint='arm_slide2' name='tj2'/>
        <!--<motor joint='gripper_jl' name='tg0' ctrllimited='false'/>-->

        <!--  ================= Position actuators ================= /-->
        <!--<position joint='arm_j0' 	name='pj0' kp='1e5' ctrlrange='-3.0503 3.0503'/>-->
        <!--<position joint='arm_j1' 	name='pj1' kp='1e5' ctrlrange='-3.8095 2.2736'/>-->
        <!--<position joint='arm_j2' 	name='pj2' kp='1e5' ctrlrange='-3.0426 3.0426'/>-->
        <!--<position joint='arm_j3' 	name='pj3' kp='2e4' ctrlrange='-3.0439 3.0439'/>-->
        <!--<position joint='arm_j4' 	name='pj4' kp='2e4' ctrlrange='-2.9761 2.9761'/>-->
        <!--<position joint='arm_j5' 	name='pj5' kp='1e3' ctrlrange='-2.9761 2.9761'/>-->
        <!--<position joint='arm_j6' 	name='pj6' kp='1e3' ctrlrange='-4.7124 4.7124'/>-->
        <!--<position joint='gripper_jr' 	name='pg1' kp='1000' ctrlrange='-0.05 0'/>-->
        <!--<position joint='gripper_jl' 	name='pg0' kp='2000' ctrlrange='0 0.05'/>-->
    </actuator>

</mujoco>
